<?xml version="1.0"?>
<robot name="otter_catamaran_model">

  <material name="white">
  	<color rgba="1.0 1.0 1.0 1" />
  </material>

  <material name="green">
  	<color rgba="0.0 1.0 0.0 1" />
  </material>
  
  <material name="blue">
  	<color rgba="0.0 0.0 1.0 1" />
  </material>

  <link name="base_link">
    <visual>
      <geometry>
        <box size="0.1 1 .05 " />
      </geometry>
	  <origin xyz="0 0 0.225" rpy="0 0 0" />
    </visual>
  </link>

  <link name="right_hull">
    <visual>
      <geometry>
        <box size="2 0.2 .2" />
      </geometry>
	  <origin xyz="0 0 0" rpy="0 0 0" />
	  <material name="blue" />
    </visual>
  </link>

  <link name="left_hull">
    <visual>
      <geometry>
        <box size="2 0.2 .2" />
      </geometry>
	  <origin xyz="0 0 0" rpy="0 0 0" />
	  <material name="blue" />
    </visual>
  </link>

  <link name="right_propeller">
    <visual>
      <geometry>
        <cylinder radius="0.015" length="0.2" />
      </geometry>
	  <origin xyz="0 0 0" rpy="0 0 0" />
	  <material name="white" />
    </visual>
  </link>

  <link name="left_propeller">
    <visual>
      <geometry>
        <cylinder radius="0.015" length="0.2" />
      </geometry>
	  <origin xyz="0 0 0" rpy="0 0 0" />
	  <material name="white" />
    </visual>
  </link>

  <link name="lidar">
    <visual>
      <geometry>
        <cylinder radius="0.05" length="0.05" />
      </geometry>
	  <origin xyz="0 0 0" rpy="0 0 0" />
	  <material name="white" />
    </visual>
  </link>

  <joint name="base_right_hull" type="fixed">
	<parent link="base_link" />
	<child link="right_hull" />
	<origin xyz="0 -0.4 0.1" rpy="0 0 0" />
  </joint>

  <joint name="base_left_hull" type="fixed">
	<parent link="base_link" />
	<child link="left_hull" />
	<origin xyz="0 0.4 .1" rpy="0 0 0" />
  </joint>

  <joint name="base_lidar" type="fixed">
	<parent link="base_link" />
	<child link="lidar" />
	<origin xyz="0 0 .275" rpy="0 0 0" />
  </joint>

  <joint name="right_hull_right_propeller" type="continuous">
	<parent link="right_hull" />
	<child link="right_propeller" />
	<origin xyz="-1 0 -0.1" rpy="0 0 0" />
	<axis xyz="1 0 0"/>
  </joint>
  
  <joint name="left_hull_left_propeller" type="continuous">
	<parent link="left_hull" />
	<child link="left_propeller" />
	<origin xyz="-1 0 -0.1" rpy="0 0 0" />
	<axis xyz="1 0 0"/>
  </joint>

</robot>
